Workbook

Sheet Sheet1
A1: Freelancer_ID | B1: Name | C1: Gender | D1: Gender | E1: Age | F1: Age | G1: Country | H1: Language | I1: Primary Skill | J1: Years Of Experience | K1: Years Of Experience | L1: Hourly Rate (USD) | M1: Hourly Rate (USD) | N1: Rating | O1: Rating | P1: Is Active | Q1: Client Satisfaction | R1: Client Satisfaction | S1: Client Satisfaction
A2: FL250001 | B2: Nicole Kidd | C2: f | D2: =IF(LEFT(C2,1)="f","Female","Male") -> Female | E2: 52 | F2: =IF(ISBLANK(E2),MEDIAN($E$2:$E$1001),E2) -> 52 | G2: Italy | H2: Italian | I2: Blockchain Development | J2: 11 | K2: =IF(ISBLANK(J2),MEDIAN($J$2:$J$1001),J2) -> 11 | L2: 100 | M2: =IF(ISBLANK(L2),MEDIAN($L$2:$L$1001),L2) -> 100 | O2: =IF(ISBLANK(N2),AVERAGE($N$2:$N$1001),N2) -> 2.5125695 | P2: No | S2: =IF(ISBLANK(R2),AVERAGE($R$2:$R$1001),R2) -> 0.79269417
A3: FL250002 | B3: Vanessa Garcia | C3: FEMALE | D3: =IF(LEFT(C3,1)="f","Female","Male") -> Female | E3: 52 | F3: =IF(ISBLANK(E3),MEDIAN($E$2:$E$1001),E3) -> 52 | G3: Australia | H3: English | I3: Mobile Apps | J3: 34 | K3: =IF(ISBLANK(J3),MEDIAN($J$2:$J$1001),J3) -> 34 | L3: 100 | M3: =IF(ISBLANK(L3),MEDIAN($L$2:$L$1001),L3) -> 100 | N3: 3.3 | O3: =IF(ISBLANK(N3),AVERAGE($N$2:$N$1001),N3) -> 3.3 | P3: Yes | Q3: 0.84 | R3: =Q3 -> 0.84 | S3: =IF(ISBLANK(R3),AVERAGE($R$2:$R$1001),R3) -> 0.84 | T3: =COUNTIF(P2:P1001,"No") -> 554 | U3: no
A4: FL250003 | B4: Juan Nelson | C4: male | D4: =IF(LEFT(C4,1)="f","Female","Male") -> Male | E4: 53 | F4: =IF(ISBLANK(E4),MEDIAN($E$2:$E$1001),E4) -> 53 | G4: Germany | H4: German | I4: Graphic Design | J4: 31 | K4: =IF(ISBLANK(J4),MEDIAN($J$2:$J$1001),J4) -> 31 | L4: 50 | M4: =IF(ISBLANK(L4),MEDIAN($L$2:$L$1001),L4) -> 50 | N4: 0 | O4: =IF(ISBLANK(N4),AVERAGE($N$2:$N$1001),N4) -> 0 | P4: No | Q4: 0.71 | R4: =Q4 -> 0.71 | S4: =IF(ISBLANK(R4),AVERAGE($R$2:$R$1001),R4) -> 0.71 | T4: =COUNTIF(P2:P1001,"Yes") -> 446 | U4: yes
A5: FL250004 | B5: Amanda Spencer | C5: F | D5: =IF(LEFT(C5,1)="f","Female","Male") -> Female | E5: 38 | F5: =IF(ISBLANK(E5),MEDIAN($E$2:$E$1001),E5) -> 38 | G5: Australia | H5: English | I5: Web Development | J5: 4 | K5: =IF(ISBLANK(J5),MEDIAN($J$2:$J$1001),J5) -> 4 | L5: 40 | M5: =IF(ISBLANK(L5),MEDIAN($L$2:$L$1001),L5) -> 40 | N5: 1.5 | O5: =IF(ISBLANK(N5),AVERAGE($N$2:$N$1001),N5) -> 1.5 | P5: No | Q5: 0.9 | R5: =Q5 -> 0.9 | S5: =IF(ISBLANK(R5),AVERAGE($R$2:$R$1001),R5) -> 0.9
A6: FL250005 | B6: Lynn Curtis | C6: female | D6: =IF(LEFT(C6,1)="f","Female","Male") -> Female | E6: 53 | F6: =IF(ISBLANK(E6),MEDIAN($E$2:$E$1001),E6) -> 53 | G6: Germany | H6: German | I6: Web Development | J6: 27 | K6: =IF(ISBLANK(J6),MEDIAN($J$2:$J$1001),J6) -> 27 | L6: 30 | M6: =IF(ISBLANK(L6),MEDIAN($L$2:$L$1001),L6) -> 30 | N6: 4.8 | O6: =IF(ISBLANK(N6),AVERAGE($N$2:$N$1001),N6) -> 4.8 | P6: No | Q6: 0.83 | R6: =Q6 -> 0.83 | S6: =IF(ISBLANK(R6),AVERAGE($R$2:$R$1001),R6) -> 0.83
A7: FL250006 | B7: Lisa Johnson | C7: female | D7: =IF(LEFT(C7,1)="f","Female","Male") -> Female | E7: 59 | F7: =IF(ISBLANK(E7),MEDIAN($E$2:$E$1001),E7) -> 59 | G7: Netherlands | H7: Dutch | I7: AI | J7: 14 | K7: =IF(ISBLANK(J7),MEDIAN($J$2:$J$1001),J7) -> 14 | L7: 30 | M7: =IF(ISBLANK(L7),MEDIAN($L$2:$L$1001),L7) -> 30 | N7: 2.4 | O7: =IF(ISBLANK(N7),AVERAGE($N$2:$N$1001),N7) -> 2.4 | P7: No | S7: =IF(ISBLANK(R7),AVERAGE($R$2:$R$1001),R7) -> 0.79269417
A8: FL250007 | B8: Eric Myers | C8: m | D8: =IF(LEFT(C8,1)="f","Female","Male") -> Male | E8: 52 | F8: =IF(ISBLANK(E8),MEDIAN($E$2:$E$1001),E8) -> 52 | G8: Indonesia | H8: Indonesian | I8: Data Analysis | J8: 10 | K8: =IF(ISBLANK(J8),MEDIAN($J$2:$J$1001),J8) -> 10 | L8: 75 | M8: =IF(ISBLANK(L8),MEDIAN($L$2:$L$1001),L8) -> 75 | N8: 3.1 | O8: =IF(ISBLANK(N8),AVERAGE($N$2:$N$1001),N8) -> 3.1 | P8: No | Q8: 0.94 | R8: =Q8 -> 0.94 | S8: =IF(ISBLANK(R8),AVERAGE($R$2:$R$1001),R8) -> 0.94
A9: FL250008 | B9: Ricky Graham | C9: male | D9: =IF(LEFT(C9,1)="f","Female","Male") -> Male | E9: 43 | F9: =IF(ISBLANK(E9),MEDIAN($E$2:$E$1001),E9) -> 43 | G9: Italy | H9: Italian | I9: Blockchain Development | J9: 14 | K9: =IF(ISBLANK(J9),MEDIAN($J$2:$J$1001),J9) -> 14 | L9: 40 | M9: =IF(ISBLANK(L9),MEDIAN($L$2:$L$1001),L9) -> 40 | N9: 4.6 | O9: =IF(ISBLANK(N9),AVERAGE($N$2:$N$1001),N9) -> 4.6 | P9: No | Q9: 0.94 | R9: =Q9 -> 0.94 | S9: =IF(ISBLANK(R9),AVERAGE($R$2:$R$1001),R9) -> 0.94
A10: FL250009 | B10: Sean Martin | C10: male | D10: =IF(LEFT(C10,1)="f","Female","Male") -> Male | E10: 26 | F10: =IF(ISBLANK(E10),MEDIAN($E$2:$E$1001),E10) -> 26 | G10: United States | H10: English | I10: Blockchain Development | J10: 4 | K10: =IF(ISBLANK(J10),MEDIAN($J$2:$J$1001),J10) -> 4 | M10: =IF(ISBLANK(L10),MEDIAN($L$2:$L$1001),L10) -> 40 | N10: 4 | O10: =IF(ISBLANK(N10),AVERAGE($N$2:$N$1001),N10) -> 4 | P10: Yes | Q10: 0.76 | R10: =Q10 -> 0.76 | S10: =IF(ISBLANK(R10),AVERAGE($R$2:$R$1001),R10) -> 0.76
A11: FL250010 | B11: Matthew Lloyd | C11: MALE | D11: =IF(LEFT(C11,1)="f","Female","Male") -> Male | E11: 52 | F11: =IF(ISBLANK(E11),MEDIAN($E$2:$E$1001),E11) -> 52 | G11: Turkey | H11: Turkish | I11: AI | J11: 22 | K11: =IF(ISBLANK(J11),MEDIAN($J$2:$J$1001),J11) -> 22 | L11: 50 | M11: =IF(ISBLANK(L11),MEDIAN($L$2:$L$1001),L11) -> 50 | O11: =IF(ISBLANK(N11),AVERAGE($N$2:$N$1001),N11) -> 2.5125695 | P11: Yes | S11: =IF(ISBLANK(R11),AVERAGE($R$2:$R$1001),R11) -> 0.79269417
A12: FL250011 | B12: Gavin Randall | C12: m | D12: =IF(LEFT(C12,1)="f","Female","Male") -> Male | E12: 40 | F12: =IF(ISBLANK(E12),MEDIAN($E$2:$E$1001),E12) -> 40 | G12: United Kingdom | H12: English | I12: Data Analysis | J12: 17 | K12: =IF(ISBLANK(J12),MEDIAN($J$2:$J$1001),J12) -> 17 | L12: 40 | M12: =IF(ISBLANK(L12),MEDIAN($L$2:$L$1001),L12) -> 40 | N12: 3.6 | O12: =IF(ISBLANK(N12),AVERAGE($N$2:$N$1001),N12) -> 3.6 | P12: Yes | Q12: 0.77 | R12: =Q12 -> 0.77 | S12: =IF(ISBLANK(R12),AVERAGE($R$2:$R$1001),R12) -> 0.77
A13: FL250012 | B13: Michelle Curtis | C13: FEMALE | D13: =IF(LEFT(C13,1)="f","Female","Male") -> Female | E13: 55 | F13: =IF(ISBLANK(E13),MEDIAN($E$2:$E$1001),E13) -> 55 | G13: Argentina | H13: Spanish | I13: UI/UX Design | J13: 15 | K13: =IF(ISBLANK(J13),MEDIAN($J$2:$J$1001),J13) -> 15 | M13: =IF(ISBLANK(L13),MEDIAN($L$2:$L$1001),L13) -> 40 | O13: =IF(ISBLANK(N13),AVERAGE($N$2:$N$1001),N13) -> 2.5125695 | P13: Yes | Q13: 0.86 | R13: =Q13 -> 0.86 | S13: =IF(ISBLANK(R13),AVERAGE($R$2:$R$1001),R13) -> 0.86
A14: FL250013 | B14: Alice Schneider | C14: Female | D14: =IF(LEFT(C14,1)="f","Female","Male") -> Female | E14: 57 | F14: =IF(ISBLANK(E14),MEDIAN($E$2:$E$1001),E14) -> 57 | G14: United Kingdom | H14: English | I14: Cybersecurity | J14: 18 | K14: =IF(ISBLANK(J14),MEDIAN($J$2:$J$1001),J14) -> 18 | M14: =IF(ISBLANK(L14),MEDIAN($L$2:$L$1001),L14) -> 40 | N14: 2 | O14: =IF(ISBLANK(N14),AVERAGE($N$2:$N$1001),N14) -> 2 | P14: No | Q14: 0.86 | R14: =Q14 -> 0.86 | S14: =IF(ISBLANK(R14),AVERAGE($R$2:$R$1001),R14) -> 0.86
A15: FL250014 | B15: Phillip Shelton | C15: MALE | D15: =IF(LEFT(C15,1)="f","Female","Male") -> Male | E15: 38 | F15: =IF(ISBLANK(E15),MEDIAN($E$2:$E$1001),E15) -> 38 | G15: Argentina | H15: Spanish | I15: Graphic Design | J15: 20 | K15: =IF(ISBLANK(J15),MEDIAN($J$2:$J$1001),J15) -> 20 | L15: 75 | M15: =IF(ISBLANK(L15),MEDIAN($L$2:$L$1001),L15) -> 75 | N15: 2.9 | O15: =IF(ISBLANK(N15),AVERAGE($N$2:$N$1001),N15) -> 2.9 | P15: Yes | Q15: 0.93 | R15: =Q15 -> 0.93 | S15: =IF(ISBLANK(R15),AVERAGE($R$2:$R$1001),R15) -> 0.93
A16: FL250015 | B16: Edward Ferguson | C16: MALE | D16: =IF(LEFT(C16,1)="f","Female","Male") -> Male | E16: 50 | F16: =IF(ISBLANK(E16),MEDIAN($E$2:$E$1001),E16) -> 50 | G16: Germany | H16: German | I16: Data Analysis | J16: 22 | K16: =IF(ISBLANK(J16),MEDIAN($J$2:$J$1001),J16) -> 22 | L16: 75 | M16: =IF(ISBLANK(L16),MEDIAN($L$2:$L$1001),L16) -> 75 | N16: 3.7 | O16: =IF(ISBLANK(N16),AVERAGE($N$2:$N$1001),N16) -> 3.7 | P16: Yes | Q16: 0.7 | R16: =Q16 -> 0.7 | S16: =IF(ISBLANK(R16),AVERAGE($R$2:$R$1001),R16) -> 0.7
A17: FL250016 | B17: Wyatt Stout | C17: m | D17: =IF(LEFT(C17,1)="f","Female","Male") -> Male | E17: 42 | F17: =IF(ISBLANK(E17),MEDIAN($E$2:$E$1001),E17) -> 42 | G17: Japan | H17: Japanese | I17: Data Analysis | J17: 0 | K17: =IF(ISBLANK(J17),MEDIAN($J$2:$J$1001),J17) -> 0 | L17: 30 | M17: =IF(ISBLANK(L17),MEDIAN($L$2:$L$1001),L17) -> 30 | N17: 1.2 | O17: =IF(ISBLANK(N17),AVERAGE($N$2:$N$1001),N17) -> 1.2 | P17: No | Q17: 0.69 | R17: =Q17 -> 0.69 | S17: =IF(ISBLANK(R17),AVERAGE($R$2:$R$1001),R17) -> 0.69
A18: FL250017 | B18: Laura Johnson | C18: Female | D18: =IF(LEFT(C18,1)="f","Female","Male") -> Female | E18: 39 | F18: =IF(ISBLANK(E18),MEDIAN($E$2:$E$1001),E18) -> 39 | G18: Australia | H18: English | I18: DevOps | J18: 13 | K18: =IF(ISBLANK(J18),MEDIAN($J$2:$J$1001),J18) -> 13 | L18: 30 | M18: =IF(ISBLANK(L18),MEDIAN($L$2:$L$1001),L18) -> 30 | N18: 2.5 | O18: =IF(ISBLANK(N18),AVERAGE($N$2:$N$1001),N18) -> 2.5 | P18: No | Q18: 0.6 | R18: =Q18 -> 0.6 | S18: =IF(ISBLANK(R18),AVERAGE($R$2:$R$1001),R18) -> 0.6
A19: FL250018 | B19: Scott Burns | C19: M | D19: =IF(LEFT(C19,1)="f","Female","Male") -> Male | E19: 56 | F19: =IF(ISBLANK(E19),MEDIAN($E$2:$E$1001),E19) -> 56 | G19: India | H19: Hindi | I19: Blockchain Development | K19: =IF(ISBLANK(J19),MEDIAN($J$2:$J$1001),J19) -> 9 | M19: =IF(ISBLANK(L19),MEDIAN($L$2:$L$1001),L19) -> 40 | O19: =IF(ISBLANK(N19),AVERAGE($N$2:$N$1001),N19) -> 2.5125695 | P19: No | Q19: 0.87 | R19: =Q19 -> 0.87 | S19: =IF(ISBLANK(R19),AVERAGE($R$2:$R$1001),R19) -> 0.87
A20: FL250019 | B20: Tyler Aguirre | C20: Male | D20: =IF(LEFT(C20,1)="f","Female","Male") -> Male | E20: 56 | F20: =IF(ISBLANK(E20),MEDIAN($E$2:$E$1001),E20) -> 56 | G20: United States | H20: English | I20: UI/UX Design | J20: 31 | K20: =IF(ISBLANK(J20),MEDIAN($J$2:$J$1001),J20) -> 31 | L20: 50 | M20: =IF(ISBLANK(L20),MEDIAN($L$2:$L$1001),L20) -> 50 | N20: 1.1 | O20: =IF(ISBLANK(N20),AVERAGE($N$2:$N$1001),N20) -> 1.1 | P20: No | Q20: 0.75 | R20: =Q20 -> 0.75 | S20: =IF(ISBLANK(R20),AVERAGE($R$2:$R$1001),R20) -> 0.75
A21: FL250020 | B21: Matthew Lawson | C21: Male | D21: =IF(LEFT(C21,1)="f","Female","Male") -> Male | E21: 57 | F21: =IF(ISBLANK(E21),MEDIAN($E$2:$E$1001),E21) -> 57 | G21: Italy | H21: Italian | I21: Web Development | J21: 3 | K21: =IF(ISBLANK(J21),MEDIAN($J$2:$J$1001),J21) -> 3 | L21: 100 | M21: =IF(ISBLANK(L21),MEDIAN($L$2:$L$1001),L21) -> 100 | N21: 1.8 | O21: =IF(ISBLANK(N21),AVERAGE($N$2:$N$1001),N21) -> 1.8 | P21: Yes | Q21: 0.68 | R21: =Q21 -> 0.68 | S21: =IF(ISBLANK(R21),AVERAGE($R$2:$R$1001),R21) -> 0.68
A22: FL250021 | B22: James Cherry | C22: Male | D22: =IF(LEFT(C22,1)="f","Female","Male") -> Male | F22: =IF(ISBLANK(E22),MEDIAN($E$2:$E$1001),E22) -> 41 | G22: Indonesia | H22: Indonesian | I22: AI | J22: 9 | K22: =IF(ISBLANK(J22),MEDIAN($J$2:$J$1001),J22) -> 9 | L22: 50 | M22: =IF(ISBLANK(L22),MEDIAN($L$2:$L$1001),L22) -> 50 | N22: 1.8 | O22: =IF(ISBLANK(N22),AVERAGE($N$2:$N$1001),N22) -> 1.8 | P22: No | Q22: 0.65 | R22: =Q22 -> 0.65 | S22: =IF(ISBLANK(R22),AVERAGE($R$2:$R$1001),R22) -> 0.65
A23: FL250022 | B23: Samuel Sanford | C23: m | D23: =IF(LEFT(C23,1)="f","Female","Male") -> Male | E23: 51 | F23: =IF(ISBLANK(E23),MEDIAN($E$2:$E$1001),E23) -> 51 | G23: Japan | H23: Japanese | I23: DevOps | K23: =IF(ISBLANK(J23),MEDIAN($J$2:$J$1001),J23) -> 9 | M23: =IF(ISBLANK(L23),MEDIAN($L$2:$L$1001),L23) -> 40 | N23: 2.4 | O23: =IF(ISBLANK(N23),AVERAGE($N$2:$N$1001),N23) -> 2.4 | P23: No | Q23: 0.69 | R23: =Q23 -> 0.69 | S23: =IF(ISBLANK(R23),AVERAGE($R$2:$R$1001),R23) -> 0.69
A24: FL250023 | B24: Cesar Greene | C24: m | D24: =IF(LEFT(C24,1)="f","Female","Male") -> Male | E24: 51 | F24: =IF(ISBLANK(E24),MEDIAN($E$2:$E$1001),E24) -> 51 | G24: Brazil | H24: Portuguese | I24: Cybersecurity | J24: 21 | K24: =IF(ISBLANK(J24),MEDIAN($J$2:$J$1001),J24) -> 21 | L24: 30 | M24: =IF(ISBLANK(L24),MEDIAN($L$2:$L$1001),L24) -> 30 | N24: 4.7 | O24: =IF(ISBLANK(N24),AVERAGE($N$2:$N$1001),N24) -> 4.7 | P24: No | S24: =IF(ISBLANK(R24),AVERAGE($R$2:$R$1001),R24) -> 0.79269417
A25: FL250024 | B25: Melanie Carter | C25: female | D25: =IF(LEFT(C25,1)="f","Female","Male") -> Female | E25: 51 | F25: =IF(ISBLANK(E25),MEDIAN($E$2:$E$1001),E25) -> 51 | G25: South Korea | H25: Korean | I25: Machine Learning | J25: 15 | K25: =IF(ISBLANK(J25),MEDIAN($J$2:$J$1001),J25) -> 15 | L25: 50 | M25: =IF(ISBLANK(L25),MEDIAN($L$2:$L$1001),L25) -> 50 | N25: 1.3 | O25: =IF(ISBLANK(N25),AVERAGE($N$2:$N$1001),N25) -> 1.3 | P25: Yes | Q25: 1 | R25: =Q25 -> 1 | S25: =IF(ISBLANK(R25),AVERAGE($R$2:$R$1001),R25) -> 1
A26: FL250025 | B26: Jennifer Martin | C26: f | D26: =IF(LEFT(C26,1)="f","Female","Male") -> Female | E26: 54 | F26: =IF(ISBLANK(E26),MEDIAN($E$2:$E$1001),E26) -> 54 | G26: Indonesia | H26: Indonesian | I26: Machine Learning | J26: 13 | K26: =IF(ISBLANK(J26),MEDIAN($J$2:$J$1001),J26) -> 13 | L26: 75 | M26: =IF(ISBLANK(L26),MEDIAN($L$2:$L$1001),L26) -> 75 | N26: 2.9 | O26: =IF(ISBLANK(N26),AVERAGE($N$2:$N$1001),N26) -> 2.9 | P26: No | Q26: 92 | R26: 0.92 | S26: =IF(ISBLANK(R26),AVERAGE($R$2:$R$1001),R26) -> 0.92
A27: FL250026 | B27: Anna Mccann | C27: FEMALE | D27: =IF(LEFT(C27,1)="f","Female","Male") -> Female | E27: 22 | F27: =IF(ISBLANK(E27),MEDIAN($E$2:$E$1001),E27) -> 22 | G27: South Korea | H27: Korean | I27: DevOps | J27: 0 | K27: =IF(ISBLANK(J27),MEDIAN($J$2:$J$1001),J27) -> 0 | L27: 30 | M27: =IF(ISBLANK(L27),MEDIAN($L$2:$L$1001),L27) -> 30 | N27: 1.2 | O27: =IF(ISBLANK(N27),AVERAGE($N$2:$N$1001),N27) -> 1.2 | P27: Yes | Q27: 0.7 | R27: =Q27 -> 0.7 | S27: =IF(ISBLANK(R27),AVERAGE($R$2:$R$1001),R27) -> 0.7
A28: FL250027 | B28: Marissa Bass | C28: female | D28: =IF(LEFT(C28,1)="f","Female","Male") -> Female | E28: 34 | F28: =IF(ISBLANK(E28),MEDIAN($E$2:$E$1001),E28) -> 34 | G28: Japan | H28: Japanese | I28: Blockchain Development | J28: 8 | K28: =IF(ISBLANK(J28),MEDIAN($J$2:$J$1001),J28) -> 8 | L28: 20 | M28: =IF(ISBLANK(L28),MEDIAN($L$2:$L$1001),L28) -> 20 | N28: 0 | O28: =IF(ISBLANK(N28),AVERAGE($N$2:$N$1001),N28) -> 0 | P28: Yes | Q28: 0.89 | R28: =Q28 -> 0.89 | S28: =IF(ISBLANK(R28),AVERAGE($R$2:$R$1001),R28) -> 0.89
A29: FL250028 | B29: Alexis Day | C29: Female | D29: =IF(LEFT(C29,1)="f","Female","Male") -> Female | E29: 36 | F29: =IF(ISBLANK(E29),MEDIAN($E$2:$E$1001),E29) -> 36 | G29: Russia | H29: Russian | I29: Graphic Design | J29: 11 | K29: =IF(ISBLANK(J29),MEDIAN($J$2:$J$1001),J29) -> 11 | M29: =IF(ISBLANK(L29),MEDIAN($L$2:$L$1001),L29) -> 40 | N29: 1.8 | O29: =IF(ISBLANK(N29),AVERAGE($N$2:$N$1001),N29) -> 1.8 | P29: Yes | Q29: 0.86 | R29: =Q29 -> 0.86 | S29: =IF(ISBLANK(R29),AVERAGE($R$2:$R$1001),R29) -> 0.86
A30: FL250029 | B30: Megan Jones | C30: female | D30: =IF(LEFT(C30,1)="f","Female","Male") -> Female | E30: 47 | F30: =IF(ISBLANK(E30),MEDIAN($E$2:$E$1001),E30) -> 47 | G30: Canada | H30: English | I30: AI | J30: 22 | K30: =IF(ISBLANK(J30),MEDIAN($J$2:$J$1001),J30) -> 22 | L30: 30 | M30: =IF(ISBLANK(L30),MEDIAN($L$2:$L$1001),L30) -> 30 | N30: 1.3 | O30: =IF(ISBLANK(N30),AVERAGE($N$2:$N$1001),N30) -> 1.3 | P30: No | Q30: 0.62 | R30: =Q30 -> 0.62 | S30: =IF(ISBLANK(R30),AVERAGE($R$2:$R$1001),R30) -> 0.62
A31: FL250030 | B31: Lori Smith | C31: FEMALE | D31: =IF(LEFT(C31,1)="f","Female","Male") -> Female | E31: 41 | F31: =IF(ISBLANK(E31),MEDIAN($E$2:$E$1001),E31) -> 41 | G31: Netherlands | H31: Dutch | I31: Data Analysis | J31: 14 | K31: =IF(ISBLANK(J31),MEDIAN($J$2:$J$1001),J31) -> 14 | L31: 75 | M31: =IF(ISBLANK(L31),MEDIAN($L$2:$L$1001),L31) -> 75 | N31: 1.2 | O31: =IF(ISBLANK(N31),AVERAGE($N$2:$N$1001),N31) -> 1.2 | P31: No | S31: =IF(ISBLANK(R31),AVERAGE($R$2:$R$1001),R31) -> 0.79269417
A32: FL250031 | B32: Eric Carpenter | C32: Male | D32: =IF(LEFT(C32,1)="f","Female","Male") -> Male | E32: 22 | F32: =IF(ISBLANK(E32),MEDIAN($E$2:$E$1001),E32) -> 22 | G32: Netherlands | H32: Dutch | I32: DevOps | J32: 4 | K32: =IF(ISBLANK(J32),MEDIAN($J$2:$J$1001),J32) -> 4 | M32: =IF(ISBLANK(L32),MEDIAN($L$2:$L$1001),L32) -> 40 | N32: 1 | O32: =IF(ISBLANK(N32),AVERAGE($N$2:$N$1001),N32) -> 1 | P32: Yes | S32: =IF(ISBLANK(R32),AVERAGE($R$2:$R$1001),R32) -> 0.79269417
A33: FL250032 | B33: Timothy Daniels | C33: Male | D33: =IF(LEFT(C33,1)="f","Female","Male") -> Male | E33: 38 | F33: =IF(ISBLANK(E33),MEDIAN($E$2:$E$1001),E33) -> 38 | G33: France | H33: French | I33: Machine Learning | J33: 19 | K33: =IF(ISBLANK(J33),MEDIAN($J$2:$J$1001),J33) -> 19 | L33: 100 | M33: =IF(ISBLANK(L33),MEDIAN($L$2:$L$1001),L33) -> 100 | N33: 4.2 | O33: =IF(ISBLANK(N33),AVERAGE($N$2:$N$1001),N33) -> 4.2 | P33: No | Q33: 0.68 | R33: =Q33 -> 0.68 | S33: =IF(ISBLANK(R33),AVERAGE($R$2:$R$1001),R33) -> 0.68
A34: FL250033 | B34: Robert Nelson | C34: M | D34: =IF(LEFT(C34,1)="f","Female","Male") -> Male | E34: 46 | F34: =IF(ISBLANK(E34),MEDIAN($E$2:$E$1001),E34) -> 46 | G34: Egypt | H34: Arabic | I34: AI | J34: 9 | K34: =IF(ISBLANK(J34),MEDIAN($J$2:$J$1001),J34) -> 9 | L34: 20 | M34: =IF(ISBLANK(L34),MEDIAN($L$2:$L$1001),L34) -> 20 | N34: 1.4 | O34: =IF(ISBLANK(N34),AVERAGE($N$2:$N$1001),N34) -> 1.4 | P34: Yes | Q34: 0.76 | R34: =Q34 -> 0.76 | S34: =IF(ISBLANK(R34),AVERAGE($R$2:$R$1001),R34) -> 0.76
A35: FL250034 | B35: Michael Anderson | C35: male | D35: =IF(LEFT(C35,1)="f","Female","Male") -> Male | F35: =IF(ISBLANK(E35),MEDIAN($E$2:$E$1001),E35) -> 41 | G35: South Korea | H35: Korean | I35: AI | J35: 9 | K35: =IF(ISBLANK(J35),MEDIAN($J$2:$J$1001),J35) -> 9 | L35: 40 | M35: =IF(ISBLANK(L35),MEDIAN($L$2:$L$1001),L35) -> 40 | N35: 2.4 | O35: =IF(ISBLANK(N35),AVERAGE($N$2:$N$1001),N35) -> 2.4 | P35: Yes | Q35: 82 | R35: 0.82 | S35: =IF(ISBLANK(R35),AVERAGE($R$2:$R$1001),R35) -> 0.82
A36: FL250035 | B36: Jessica Snyder | C36: FEMALE | D36: =IF(LEFT(C36,1)="f","Female","Male") -> Female | E36: 54 | F36: =IF(ISBLANK(E36),MEDIAN($E$2:$E$1001),E36) -> 54 | G36: United States | H36: English | I36: Web Development | J36: 32 | K36: =IF(ISBLANK(J36),MEDIAN($J$2:$J$1001),J36) -> 32 | L36: 75 | M36: =IF(ISBLANK(L36),MEDIAN($L$2:$L$1001),L36) -> 75 | N36: 1 | O36: =IF(ISBLANK(N36),AVERAGE($N$2:$N$1001),N36) -> 1 | P36: Yes | Q36: 0.81 | R36: =Q36 -> 0.81 | S36: =IF(ISBLANK(R36),AVERAGE($R$2:$R$1001),R36) -> 0.81
A37: FL250036 | B37: Emily Daniels | C37: female | D37: =IF(LEFT(C37,1)="f","Female","Male") -> Female | E37: 52 | F37: =IF(ISBLANK(E37),MEDIAN($E$2:$E$1001),E37) -> 52 | G37: South Korea | H37: Korean | I37: Web Development | J37: 28 | K37: =IF(ISBLANK(J37),MEDIAN($J$2:$J$1001),J37) -> 28 | L37: 20 | M37: =IF(ISBLANK(L37),MEDIAN($L$2:$L$1001),L37) -> 20 | O37: =IF(ISBLANK(N37),AVERAGE($N$2:$N$1001),N37) -> 2.5125695 | P37: No | S37: =IF(ISBLANK(R37),AVERAGE($R$2:$R$1001),R37) -> 0.79269417
A38: FL250037 | B38: Jamie Ramirez | C38: f | D38: =IF(LEFT(C38,1)="f","Female","Male") -> Female | E38: 42 | F38: =IF(ISBLANK(E38),MEDIAN($E$2:$E$1001),E38) -> 42 | G38: Japan | H38: Japanese | I38: Mobile Apps | J38: 6 | K38: =IF(ISBLANK(J38),MEDIAN($J$2:$J$1001),J38) -> 6 | L38: 40 | M38: =IF(ISBLANK(L38),MEDIAN($L$2:$L$1001),L38) -> 40 | O38: =IF(ISBLANK(N38),AVERAGE($N$2:$N$1001),N38) -> 2.5125695 | P38: No | Q38: 0.63 | R38: =Q38 -> 0.63 | S38: =IF(ISBLANK(R38),AVERAGE($R$2:$R$1001),R38) -> 0.63
A39: FL250038 | B39: Amy Harrison | C39: F | D39: =IF(LEFT(C39,1)="f","Female","Male") -> Female | E39: 29 | F39: =IF(ISBLANK(E39),MEDIAN($E$2:$E$1001),E39) -> 29 | G39: Netherlands | H39: Dutch | I39: Graphic Design | J39: 10 | K39: =IF(ISBLANK(J39),MEDIAN($J$2:$J$1001),J39) -> 10 | L39: 40 | M39: =IF(ISBLANK(L39),MEDIAN($L$2:$L$1001),L39) -> 40 | N39: 2.2 | O39: =IF(ISBLANK(N39),AVERAGE($N$2:$N$1001),N39) -> 2.2 | P39: No | Q39: 0.67 | R39: =Q39 -> 0.67 | S39: =IF(ISBLANK(R39),AVERAGE($R$2:$R$1001),R39) -> 0.67
A40: FL250039 | B40: Melinda White | C40: F | D40: =IF(LEFT(C40,1)="f","Female","Male") -> Female | E40: 42 | F40: =IF(ISBLANK(E40),MEDIAN($E$2:$E$1001),E40) -> 42 | G40: South Africa | H40: Afrikaans | I40: Mobile Apps | J40: 23 | K40: =IF(ISBLANK(J40),MEDIAN($J$2:$J$1001),J40) -> 23 | L40: 50 | M40: =IF(ISBLANK(L40),MEDIAN($L$2:$L$1001),L40) -> 50 | N40: 3.2 | O40: =IF(ISBLANK(N40),AVERAGE($N$2:$N$1001),N40) -> 3.2 | P40: Yes | S40: =IF(ISBLANK(R40),AVERAGE($R$2:$R$1001),R40) -> 0.79269417
...

Sheet Cleaned Data
A1: Freelancer_ID | B1: Name | C1: Gender | D1: Age | E1: Country | F1: Language | G1: Primary Skill | H1: Years Of Experience | I1: Hourly Rate (USD) | J1: Rating | K1: Is Active | L1: Client Satisfaction
A2: FL250001 | B2: =_xlfn.XLOOKUP(A2,Sheet1!A:A,Sheet1!B:B) -> Nicole Kidd | C2: =_xlfn.XLOOKUP(A:A,Sheet1!A:A,Sheet1!D:D) -> Female | D2: =_xlfn.XLOOKUP(A:A,Sheet1!A:A,Sheet1!F:F) -> 52 | E2: =_xlfn.XLOOKUP(A:A,Sheet1!A:A,Sheet1!G:G) -> Italy | F2: =_xlfn.XLOOKUP(A:A,Sheet1!A:A,Sheet1!H:H) -> Italian | G2: =_xlfn.XLOOKUP(A:A,Sheet1!A:A,Sheet1!I:I) -> Blockchain Development | H2: =_xlfn.XLOOKUP(A:A,Sheet1!A:A,Sheet1!K:K) -> 11 | I2: =_xlfn.XLOOKUP(A:A,Sheet1!A:A,Sheet1!M:M) -> 100 | J2: =_xlfn.XLOOKUP(A:A,Sheet1!A:A,Sheet1!O:O) -> 2.5125695 | K2: =_xlfn.XLOOKUP(A:A,Sheet1!A:A,Sheet1!P:P) -> No | L2: =_xlfn.XLOOKUP(A:A,Sheet1!A:A,Sheet1!S:S) -> 0.79269417
A3: FL250002 | B3: =_xlfn.XLOOKUP(A3,Sheet1!A:A,Sheet1!B:B) -> Vanessa Garcia | C3: =_xlfn.XLOOKUP(A:A,Sheet1!A:A,Sheet1!D:D) -> Female | D3: =_xlfn.XLOOKUP(A:A,Sheet1!A:A,Sheet1!F:F) -> 52 | E3: =_xlfn.XLOOKUP(A:A,Sheet1!A:A,Sheet1!G:G) -> Australia | F3: =_xlfn.XLOOKUP(A:A,Sheet1!A:A,Sheet1!H:H) -> English | G3: =_xlfn.XLOOKUP(A:A,Sheet1!A:A,Sheet1!I:I) -> Mobile Apps | H3: =_xlfn.XLOOKUP(A:A,Sheet1!A:A,Sheet1!K:K) -> 34 | I3: =_xlfn.XLOOKUP(A:A,Sheet1!A:A,Sheet1!M:M) -> 100 | J3: =_xlfn.XLOOKUP(A:A,Sheet1!A:A,Sheet1!O:O) -> 3.3 | K3: =_xlfn.XLOOKUP(A:A,Sheet1!A:A,Sheet1!P:P) -> Yes | L3: =_xlfn.XLOOKUP(A:A,Sheet1!A:A,Sheet1!S:S) -> 0.84
A4: FL250003 | B4: =_xlfn.XLOOKUP(A4,Sheet1!A:A,Sheet1!B:B) -> Juan Nelson | C4: =_xlfn.XLOOKUP(A:A,Sheet1!A:A,Sheet1!D:D) -> Male | D4: =_xlfn.XLOOKUP(A:A,Sheet1!A:A,Sheet1!F:F) -> 53 | E4: =_xlfn.XLOOKUP(A:A,Sheet1!A:A,Sheet1!G:G) -> Germany | F4: =_xlfn.XLOOKUP(A:A,Sheet1!A:A,Sheet1!H:H) -> German | G4: =_xlfn.XLOOKUP(A:A,Sheet1!A:A,Sheet1!I:I) -> Graphic Design | H4: =_xlfn.XLOOKUP(A:A,Sheet1!A:A,Sheet1!K:K) -> 31 | I4: =_xlfn.XLOOKUP(A:A,Sheet1!A:A,Sheet1!M:M) -> 50 | J4: 0 | K4: =_xlfn.XLOOKUP(A:A,Sheet1!A:A,Sheet1!P:P) -> No | L4: =_xlfn.XLOOKUP(A:A,Sheet1!A:A,Sheet1!S:S) -> 0.71
A5: FL250004 | B5: =_xlfn.XLOOKUP(A5,Sheet1!A:A,Sheet1!B:B) -> Amanda Spencer | C5: =_xlfn.XLOOKUP(A:A,Sheet1!A:A,Sheet1!D:D) -> Female | D5: =_xlfn.XLOOKUP(A:A,Sheet1!A:A,Sheet1!F:F) -> 38 | E5: =_xlfn.XLOOKUP(A:A,Sheet1!A:A,Sheet1!G:G) -> Australia | F5: =_xlfn.XLOOKUP(A:A,Sheet1!A:A,Sheet1!H:H) -> English | G5: =_xlfn.XLOOKUP(A:A,Sheet1!A:A,Sheet1!I:I) -> Web Development | H5: =_xlfn.XLOOKUP(A:A,Sheet1!A:A,Sheet1!K:K) -> 4 | I5: =_xlfn.XLOOKUP(A:A,Sheet1!A:A,Sheet1!M:M) -> 40 | J5: =_xlfn.XLOOKUP(A:A,Sheet1!A:A,Sheet1!O:O) -> 1.5 | K5: =_xlfn.XLOOKUP(A:A,Sheet1!A:A,Sheet1!P:P) -> No | L5: =_xlfn.XLOOKUP(A:A,Sheet1!A:A,Sheet1!S:S) -> 0.9
A6: FL250005 | B6: =_xlfn.XLOOKUP(A6,Sheet1!A:A,Sheet1!B:B) -> Lynn Curtis | C6: =_xlfn.XLOOKUP(A:A,Sheet1!A:A,Sheet1!D:D) -> Female | D6: =_xlfn.XLOOKUP(A:A,Sheet1!A:A,Sheet1!F:F) -> 53 | E6: =_xlfn.XLOOKUP(A:A,Sheet1!A:A,Sheet1!G:G) -> Germany | F6: =_xlfn.XLOOKUP(A:A,Sheet1!A:A,Sheet1!H:H) -> German | G6: =_xlfn.XLOOKUP(A:A,Sheet1!A:A,Sheet1!I:I) -> Web Development | H6: =_xlfn.XLOOKUP(A:A,Sheet1!A:A,Sheet1!K:K) -> 27 | I6: =_xlfn.XLOOKUP(A:A,Sheet1!A:A,Sheet1!M:M) -> 30 | J6: =_xlfn.XLOOKUP(A:A,Sheet1!A:A,Sheet1!O:O) -> 4.8 | K6: =_xlfn.XLOOKUP(A:A,Sheet1!A:A,Sheet1!P:P) -> No | L6: =_xlfn.XLOOKUP(A:A,Sheet1!A:A,Sheet1!S:S) -> 0.83
A7: FL250006 | B7: =_xlfn.XLOOKUP(A7,Sheet1!A:A,Sheet1!B:B) -> Lisa Johnson | C7: =_xlfn.XLOOKUP(A:A,Sheet1!A:A,Sheet1!D:D) -> Female | D7: =_xlfn.XLOOKUP(A:A,Sheet1!A:A,Sheet1!F:F) -> 59 | E7: =_xlfn.XLOOKUP(A:A,Sheet1!A:A,Sheet1!G:G) -> Netherlands | F7: =_xlfn.XLOOKUP(A:A,Sheet1!A:A,Sheet1!H:H) -> Dutch | G7: =_xlfn.XLOOKUP(A:A,Sheet1!A:A,Sheet1!I:I) -> AI | H7: =_xlfn.XLOOKUP(A:A,Sheet1!A:A,Sheet1!K:K) -> 14 | I7: =_xlfn.XLOOKUP(A:A,Sheet1!A:A,Sheet1!M:M) -> 30 | J7: =_xlfn.XLOOKUP(A:A,Sheet1!A:A,Sheet1!O:O) -> 2.4 | K7: =_xlfn.XLOOKUP(A:A,Sheet1!A:A,Sheet1!P:P) -> No | L7: =_xlfn.XLOOKUP(A:A,Sheet1!A:A,Sheet1!S:S) -> 0.79269417
A8: FL250007 | B8: =_xlfn.XLOOKUP(A8,Sheet1!A:A,Sheet1!B:B) -> Eric Myers | C8: =_xlfn.XLOOKUP(A:A,Sheet1!A:A,Sheet1!D:D) -> Male | D8: =_xlfn.XLOOKUP(A:A,Sheet1!A:A,Sheet1!F:F) -> 52 | E8: =_xlfn.XLOOKUP(A:A,Sheet1!A:A,Sheet1!G:G) -> Indonesia | F8: =_xlfn.XLOOKUP(A:A,Sheet1!A:A,Sheet1!H:H) -> Indonesian | G8: =_xlfn.XLOOKUP(A:A,Sheet1!A:A,Sheet1!I:I) -> Data Analysis | H8: =_xlfn.XLOOKUP(A:A,Sheet1!A:A,Sheet1!K:K) -> 10 | I8: =_xlfn.XLOOKUP(A:A,Sheet1!A:A,Sheet1!M:M) -> 75 | J8: =_xlfn.XLOOKUP(A:A,Sheet1!A:A,Sheet1!O:O) -> 3.1 | K8: =_xlfn.XLOOKUP(A:A,Sheet1!A:A,Sheet1!P:P) -> No | L8: =_xlfn.XLOOKUP(A:A,Sheet1!A:A,Sheet1!S:S) -> 0.94
A9: FL250008 | B9: =_xlfn.XLOOKUP(A9,Sheet1!A:A,Sheet1!B:B) -> Ricky Graham | C9: =_xlfn.XLOOKUP(A:A,Sheet1!A:A,Sheet1!D:D) -> Male | D9: =_xlfn.XLOOKUP(A:A,Sheet1!A:A,Sheet1!F:F) -> 43 | E9: =_xlfn.XLOOKUP(A:A,Sheet1!A:A,Sheet1!G:G) -> Italy | F9: =_xlfn.XLOOKUP(A:A,Sheet1!A:A,Sheet1!H:H) -> Italian | G9: =_xlfn.XLOOKUP(A:A,Sheet1!A:A,Sheet1!I:I) -> Blockchain Development | H9: =_xlfn.XLOOKUP(A:A,Sheet1!A:A,Sheet1!K:K) -> 14 | I9: =_xlfn.XLOOKUP(A:A,Sheet1!A:A,Sheet1!M:M) -> 40 | J9: =_xlfn.XLOOKUP(A:A,Sheet1!A:A,Sheet1!O:O) -> 4.6 | K9: =_xlfn.XLOOKUP(A:A,Sheet1!A:A,Sheet1!P:P) -> No | L9: =_xlfn.XLOOKUP(A:A,Sheet1!A:A,Sheet1!S:S) -> 0.94
A10: FL250009 | B10: =_xlfn.XLOOKUP(A10,Sheet1!A:A,Sheet1!B:B) -> Sean Martin | C10: =_xlfn.XLOOKUP(A:A,Sheet1!A:A,Sheet1!D:D) -> Male | D10: =_xlfn.XLOOKUP(A:A,Sheet1!A:A,Sheet1!F:F) -> 26 | E10: =_xlfn.XLOOKUP(A:A,Sheet1!A:A,Sheet1!G:G) -> United States | F10: =_xlfn.XLOOKUP(A:A,Sheet1!A:A,Sheet1!H:H) -> English | G10: =_xlfn.XLOOKUP(A:A,Sheet1!A:A,Sheet1!I:I) -> Blockchain Development | H10: =_xlfn.XLOOKUP(A:A,Sheet1!A:A,Sheet1!K:K) -> 4 | I10: =_xlfn.XLOOKUP(A:A,Sheet1!A:A,Sheet1!M:M) -> 40 | J10: =_xlfn.XLOOKUP(A:A,Sheet1!A:A,Sheet1!O:O) -> 4 | K10: =_xlfn.XLOOKUP(A:A,Sheet1!A:A,Sheet1!P:P) -> Yes | L10: =_xlfn.XLOOKUP(A:A,Sheet1!A:A,Sheet1!S:S) -> 0.76
A11: FL250010 | B11: =_xlfn.XLOOKUP(A11,Sheet1!A:A,Sheet1!B:B) -> Matthew Lloyd | C11: =_xlfn.XLOOKUP(A:A,Sheet1!A:A,Sheet1!D:D) -> Male | D11: =_xlfn.XLOOKUP(A:A,Sheet1!A:A,Sheet1!F:F) -> 52 | E11: =_xlfn.XLOOKUP(A:A,Sheet1!A:A,Sheet1!G:G) -> Turkey | F11: =_xlfn.XLOOKUP(A:A,Sheet1!A:A,Sheet1!H:H) -> Turkish | G11: =_xlfn.XLOOKUP(A:A,Sheet1!A:A,Sheet1!I:I) -> AI | H11: =_xlfn.XLOOKUP(A:A,Sheet1!A:A,Sheet1!K:K) -> 22 | I11: =_xlfn.XLOOKUP(A:A,Sheet1!A:A,Sheet1!M:M) -> 50 | J11: =_xlfn.XLOOKUP(A:A,Sheet1!A:A,Sheet1!O:O) -> 2.5125695 | K11: =_xlfn.XLOOKUP(A:A,Sheet1!A:A,Sheet1!P:P) -> Yes | L11: =_xlfn.XLOOKUP(A:A,Sheet1!A:A,Sheet1!S:S) -> 0.79269417
A12: FL250011 | B12: =_xlfn.XLOOKUP(A12,Sheet1!A:A,Sheet1!B:B) -> Gavin Randall | C12: =_xlfn.XLOOKUP(A:A,Sheet1!A:A,Sheet1!D:D) -> Male | D12: =_xlfn.XLOOKUP(A:A,Sheet1!A:A,Sheet1!F:F) -> 40 | E12: =_xlfn.XLOOKUP(A:A,Sheet1!A:A,Sheet1!G:G) -> United Kingdom | F12: =_xlfn.XLOOKUP(A:A,Sheet1!A:A,Sheet1!H:H) -> English | G12: =_xlfn.XLOOKUP(A:A,Sheet1!A:A,Sheet1!I:I) -> Data Analysis | H12: =_xlfn.XLOOKUP(A:A,Sheet1!A:A,Sheet1!K:K) -> 17 | I12: =_xlfn.XLOOKUP(A:A,Sheet1!A:A,Sheet1!M:M) -> 40 | J12: =_xlfn.XLOOKUP(A:A,Sheet1!A:A,Sheet1!O:O) -> 3.6 | K12: =_xlfn.XLOOKUP(A:A,Sheet1!A:A,Sheet1!P:P) -> Yes | L12: =_xlfn.XLOOKUP(A:A,Sheet1!A:A,Sheet1!S:S) -> 0.77
A13: FL250012 | B13: =_xlfn.XLOOKUP(A13,Sheet1!A:A,Sheet1!B:B) -> Michelle Curtis | C13: =_xlfn.XLOOKUP(A:A,Sheet1!A:A,Sheet1!D:D) -> Female | D13: =_xlfn.XLOOKUP(A:A,Sheet1!A:A,Sheet1!F:F) -> 55 | E13: =_xlfn.XLOOKUP(A:A,Sheet1!A:A,Sheet1!G:G) -> Argentina | F13: =_xlfn.XLOOKUP(A:A,Sheet1!A:A,Sheet1!H:H) -> Spanish | G13: =_xlfn.XLOOKUP(A:A,Sheet1!A:A,Sheet1!I:I) -> UI/UX Design | H13: =_xlfn.XLOOKUP(A:A,Sheet1!A:A,Sheet1!K:K) -> 15 | I13: =_xlfn.XLOOKUP(A:A,Sheet1!A:A,Sheet1!M:M) -> 40 | J13: =_xlfn.XLOOKUP(A:A,Sheet1!A:A,Sheet1!O:O) -> 2.5125695 | K13: =_xlfn.XLOOKUP(A:A,Sheet1!A:A,Sheet1!P:P) -> Yes | L13: =_xlfn.XLOOKUP(A:A,Sheet1!A:A,Sheet1!S:S) -> 0.86
A14: FL250013 | B14: =_xlfn.XLOOKUP(A14,Sheet1!A:A,Sheet1!B:B) -> Alice Schneider | C14: =_xlfn.XLOOKUP(A:A,Sheet1!A:A,Sheet1!D:D) -> Female | D14: =_xlfn.XLOOKUP(A:A,Sheet1!A:A,Sheet1!F:F) -> 57 | E14: =_xlfn.XLOOKUP(A:A,Sheet1!A:A,Sheet1!G:G) -> United Kingdom | F14: =_xlfn.XLOOKUP(A:A,Sheet1!A:A,Sheet1!H:H) -> English | G14: =_xlfn.XLOOKUP(A:A,Sheet1!A:A,Sheet1!I:I) -> Cybersecurity | H14: =_xlfn.XLOOKUP(A:A,Sheet1!A:A,Sheet1!K:K) -> 18 | I14: =_xlfn.XLOOKUP(A:A,Sheet1!A:A,Sheet1!M:M) -> 40 | J14: =_xlfn.XLOOKUP(A:A,Sheet1!A:A,Sheet1!O:O) -> 2 | K14: =_xlfn.XLOOKUP(A:A,Sheet1!A:A,Sheet1!P:P) -> No | L14: =_xlfn.XLOOKUP(A:A,Sheet1!A:A,Sheet1!S:S) -> 0.86
A15: FL250014 | B15: =_xlfn.XLOOKUP(A15,Sheet1!A:A,Sheet1!B:B) -> Phillip Shelton | C15: =_xlfn.XLOOKUP(A:A,Sheet1!A:A,Sheet1!D:D) -> Male | D15: =_xlfn.XLOOKUP(A:A,Sheet1!A:A,Sheet1!F:F) -> 38 | E15: =_xlfn.XLOOKUP(A:A,Sheet1!A:A,Sheet1!G:G) -> Argentina | F15: =_xlfn.XLOOKUP(A:A,Sheet1!A:A,Sheet1!H:H) -> Spanish | G15: =_xlfn.XLOOKUP(A:A,Sheet1!A:A,Sheet1!I:I) -> Graphic Design | H15: =_xlfn.XLOOKUP(A:A,Sheet1!A:A,Sheet1!K:K) -> 20 | I15: =_xlfn.XLOOKUP(A:A,Sheet1!A:A,Sheet1!M:M) -> 75 | J15: =_xlfn.XLOOKUP(A:A,Sheet1!A:A,Sheet1!O:O) -> 2.9 | K15: =_xlfn.XLOOKUP(A:A,Sheet1!A:A,Sheet1!P:P) -> Yes | L15: =_xlfn.XLOOKUP(A:A,Sheet1!A:A,Sheet1!S:S) -> 0.93
A16: FL250015 | B16: =_xlfn.XLOOKUP(A16,Sheet1!A:A,Sheet1!B:B) -> Edward Ferguson | C16: =_xlfn.XLOOKUP(A:A,Sheet1!A:A,Sheet1!D:D) -> Male | D16: =_xlfn.XLOOKUP(A:A,Sheet1!A:A,Sheet1!F:F) -> 50 | E16: =_xlfn.XLOOKUP(A:A,Sheet1!A:A,Sheet1!G:G) -> Germany | F16: =_xlfn.XLOOKUP(A:A,Sheet1!A:A,Sheet1!H:H) -> German | G16: =_xlfn.XLOOKUP(A:A,Sheet1!A:A,Sheet1!I:I) -> Data Analysis | H16: =_xlfn.XLOOKUP(A:A,Sheet1!A:A,Sheet1!K:K) -> 22 | I16: =_xlfn.XLOOKUP(A:A,Sheet1!A:A,Sheet1!M:M) -> 75 | J16: =_xlfn.XLOOKUP(A:A,Sheet1!A:A,Sheet1!O:O) -> 3.7 | K16: =_xlfn.XLOOKUP(A:A,Sheet1!A:A,Sheet1!P:P) -> Yes | L16: =_xlfn.XLOOKUP(A:A,Sheet1!A:A,Sheet1!S:S) -> 0.7
... A27: FL250026 | B27: =_xlfn.XLOOKUP(A27,Sheet1!A:A,Sheet1!B:B) -> Anna Mccann | C27: =_xlfn.XLOOKUP(A:A,Sheet1!A:A,Sheet1!D:D) -> Female | D27: =_xlfn.XLOOKUP(A:A,Sheet1!A:A,Sheet1!F:F) -> 22 | E27: =_xlfn.XLOOKUP(A:A,Sheet1!A:A,Sheet1!G:G) -> South Korea | F27: =_xlfn.XLOOKUP(A:A,Sheet1!A:A,Sheet1!H:H) -> Korean | G27: =_xlfn.XLOOKUP(A:A,Sheet1!A:A,Sheet1!I:I) -> DevOps | H27: =_xlfn.XLOOKUP(A:A,Sheet1!A:A,Sheet1!K:K) -> 0 | I27: =_xlfn.XLOOKUP(A:A,Sheet1!A:A,Sheet1!M:M) -> 30 | J27: =_xlfn.XLOOKUP(A:A,Sheet1!A:A,Sheet1!O:O) -> 1.2 | K27: =_xlfn.XLOOKUP(A:A,Sheet1!A:A,Sheet1!P:P) -> Yes | L27: =_xlfn.XLOOKUP(A:A,Sheet1!A:A,Sheet1!S:S) -> 0.7
A28: FL250027 | B28: =_xlfn.XLOOKUP(A28,Sheet1!A:A,Sheet1!B:B) -> Marissa Bass | C28: =_xlfn.XLOOKUP(A:A,Sheet1!A:A,Sheet1!D:D) -> Female | D28: =_xlfn.XLOOKUP(A:A,Sheet1!A:A,Sheet1!F:F) -> 34 | E28: =_xlfn.XLOOKUP(A:A,Sheet1!A:A,Sheet1!G:G) -> Japan | F28: =_xlfn.XLOOKUP(A:A,Sheet1!A:A,Sheet1!H:H) -> Japanese | G28: =_xlfn.XLOOKUP(A:A,Sheet1!A:A,Sheet1!I:I) -> Blockchain Development | H28: =_xlfn.XLOOKUP(A:A,Sheet1!A:A,Sheet1!K:K) -> 8 | I28: =_xlfn.XLOOKUP(A:A,Sheet1!A:A,Sheet1!M:M) -> 20 | J28: 0 | K28: =_xlfn.XLOOKUP(A:A,Sheet1!A:A,Sheet1!P:P) -> Yes | L28: =_xlfn.XLOOKUP(A:A,Sheet1!A:A,Sheet1!S:S) -> 0.89
A29: FL250028 | B29: =_xlfn.XLOOKUP(A29,Sheet1!A:A,Sheet1!B:B) -> Alexis Day | C29: =_xlfn.XLOOKUP(A:A,Sheet1!A:A,Sheet1!D:D) -> Female | D29: =_xlfn.XLOOKUP(A:A,Sheet1!A:A,Sheet1!F:F) -> 36 | E29: =_xlfn.XLOOKUP(A:A,Sheet1!A:A,Sheet1!G:G) -> Russia | F29: =_xlfn.XLOOKUP(A:A,Sheet1!A:A,Sheet1!H:H) -> Russian | G29: =_xlfn.XLOOKUP(A:A,Sheet1!A:A,Sheet1!I:I) -> Graphic Design | H29: =_xlfn.XLOOKUP(A:A,Sheet1!A:A,Sheet1!K:K) -> 11 | I29: =_xlfn.XLOOKUP(A:A,Sheet1!A:A,Sheet1!M:M) -> 40 | J29: =_xlfn.XLOOKUP(A:A,Sheet1!A:A,Sheet1!O:O) -> 1.8 | K29: =_xlfn.XLOOKUP(A:A,Sheet1!A:A,Sheet1!P:P) -> Yes | L29: =_xlfn.XLOOKUP(A:A,Sheet1!A:A,Sheet1!S:S) -> 0.86
A30: FL250029 | B30: =_xlfn.XLOOKUP(A30,Sheet1!A:A,Sheet1!B:B) -> Megan Jones | C30: =_xlfn.XLOOKUP(A:A,Sheet1!A:A,Sheet1!D:D) -> Female | D30: =_xlfn.XLOOKUP(A:A,Sheet1!A:A,Sheet1!F:F) -> 47 | E30: =_xlfn.XLOOKUP(A:A,Sheet1!A:A,Sheet1!G:G) -> Canada | F30: =_xlfn.XLOOKUP(A:A,Sheet1!A:A,Sheet1!H:H) -> English | G30: =_xlfn.XLOOKUP(A:A,Sheet1!A:A,Sheet1!I:I) -> AI | H30: =_xlfn.XLOOKUP(A:A,Sheet1!A:A,Sheet1!K:K) -> 22 | I30: =_xlfn.XLOOKUP(A:A,Sheet1!A:A,Sheet1!M:M) -> 30 | J30: =_xlfn.XLOOKUP(A:A,Sheet1!A:A,Sheet1!O:O) -> 1.3 | K30: =_xlfn.XLOOKUP(A:A,Sheet1!A:A,Sheet1!P:P) -> No | L30: =_xlfn.XLOOKUP(A:A,Sheet1!A:A,Sheet1!S:S) -> 0.62
A31: FL250030 | B31: =_xlfn.XLOOKUP(A31,Sheet1!A:A,Sheet1!B:B) -> Lori Smith | C31: =_xlfn.XLOOKUP(A:A,Sheet1!A:A,Sheet1!D:D) -> Female | D31: =_xlfn.XLOOKUP(A:A,Sheet1!A:A,Sheet1!F:F) -> 41 | E31: =_xlfn.XLOOKUP(A:A,Sheet1!A:A,Sheet1!G:G) -> Netherlands | F31: =_xlfn.XLOOKUP(A:A,Sheet1!A:A,Sheet1!H:H) -> Dutch | G31: =_xlfn.XLOOKUP(A:A,Sheet1!A:A,Sheet1!I:I) -> Data Analysis | H31: =_xlfn.XLOOKUP(A:A,Sheet1!A:A,Sheet1!K:K) -> 14 | I31: =_xlfn.XLOOKUP(A:A,Sheet1!A:A,Sheet1!M:M) -> 75 | J31: =_xlfn.XLOOKUP(A:A,Sheet1!A:A,Sheet1!O:O) -> 1.2 | K31: =_xlfn.XLOOKUP(A:A,Sheet1!A:A,Sheet1!P:P) -> No | L31: =_xlfn.XLOOKUP(A:A,Sheet1!A:A,Sheet1!S:S) -> 0.79269417
A32: FL250031 | B32: =_xlfn.XLOOKUP(A32,Sheet1!A:A,Sheet1!B:B) -> Eric Carpenter | C32: =_xlfn.XLOOKUP(A:A,Sheet1!A:A,Sheet1!D:D) -> Male | D32: =_xlfn.XLOOKUP(A:A,Sheet1!A:A,Sheet1!F:F) -> 22 | E32: =_xlfn.XLOOKUP(A:A,Sheet1!A:A,Sheet1!G:G) -> Netherlands | F32: =_xlfn.XLOOKUP(A:A,Sheet1!A:A,Sheet1!H:H) -> Dutch | G32: =_xlfn.XLOOKUP(A:A,Sheet1!A:A,Sheet1!I:I) -> DevOps | H32: =_xlfn.XLOOKUP(A:A,Sheet1!A:A,Sheet1!K:K) -> 4 | I32: =_xlfn.XLOOKUP(A:A,Sheet1!A:A,Sheet1!M:M) -> 40 | J32: =_xlfn.XLOOKUP(A:A,Sheet1!A:A,Sheet1!O:O) -> 1 | K32: =_xlfn.XLOOKUP(A:A,Sheet1!A:A,Sheet1!P:P) -> Yes | L32: =_xlfn.XLOOKUP(A:A,Sheet1!A:A,Sheet1!S:S) -> 0.79269417
A33: FL250032 | B33: =_xlfn.XLOOKUP(A33,Sheet1!A:A,Sheet1!B:B) -> Timothy Daniels | C33: =_xlfn.XLOOKUP(A:A,Sheet1!A:A,Sheet1!D:D) -> Male | D33: =_xlfn.XLOOKUP(A:A,Sheet1!A:A,Sheet1!F:F) -> 38 | E33: =_xlfn.XLOOKUP(A:A,Sheet1!A:A,Sheet1!G:G) -> France | F33: =_xlfn.XLOOKUP(A:A,Sheet1!A:A,Sheet1!H:H) -> French | G33: =_xlfn.XLOOKUP(A:A,Sheet1!A:A,Sheet1!I:I) -> Machine Learning | H33: =_xlfn.XLOOKUP(A:A,Sheet1!A:A,Sheet1!K:K) -> 19 | I33: =_xlfn.XLOOKUP(A:A,Sheet1!A:A,Sheet1!M:M) -> 100 | J33: =_xlfn.XLOOKUP(A:A,Sheet1!A:A,Sheet1!O:O) -> 4.2 | K33: =_xlfn.XLOOKUP(A:A,Sheet1!A:A,Sheet1!P:P) -> No | L33: =_xlfn.XLOOKUP(A:A,Sheet1!A:A,Sheet1!S:S) -> 0.68
A34: FL250033 | B34: =_xlfn.XLOOKUP(A34,Sheet1!A:A,Sheet1!B:B) -> Robert Nelson | C34: =_xlfn.XLOOKUP(A:A,Sheet1!A:A,Sheet1!D:D) -> Male | D34: =_xlfn.XLOOKUP(A:A,Sheet1!A:A,Sheet1!F:F) -> 46 | E34: =_xlfn.XLOOKUP(A:A,Sheet1!A:A,Sheet1!G:G) -> Egypt | F34: =_xlfn.XLOOKUP(A:A,Sheet1!A:A,Sheet1!H:H) -> Arabic | G34: =_xlfn.XLOOKUP(A:A,Sheet1!A:A,Sheet1!I:I) -> AI | H34: =_xlfn.XLOOKUP(A:A,Sheet1!A:A,Sheet1!K:K) -> 9 | I34: =_xlfn.XLOOKUP(A:A,Sheet1!A:A,Sheet1!M:M) -> 20 | J34: =_xlfn.XLOOKUP(A:A,Sheet1!A:A,Sheet1!O:O) -> 1.4 | K34: =_xlfn.XLOOKUP(A:A,Sheet1!A:A,Sheet1!P:P) -> Yes | L34: =_xlfn.XLOOKUP(A:A,Sheet1!A:A,Sheet1!S:S) -> 0.76
A35: FL250034 | B35: =_xlfn.XLOOKUP(A35,Sheet1!A:A,Sheet1!B:B) -> Michael Anderson | C35: =_xlfn.XLOOKUP(A:A,Sheet1!A:A,Sheet1!D:D) -> Male | D35: =_xlfn.XLOOKUP(A:A,Sheet1!A:A,Sheet1!F:F) -> 41 | E35: =_xlfn.XLOOKUP(A:A,Sheet1!A:A,Sheet1!G:G) -> South Korea | F35: =_xlfn.XLOOKUP(A:A,Sheet1!A:A,Sheet1!H:H) -> Korean | G35: =_xlfn.XLOOKUP(A:A,Sheet1!A:A,Sheet1!I:I) -> AI | H35: =_xlfn.XLOOKUP(A:A,Sheet1!A:A,Sheet1!K:K) -> 9 | I35: =_xlfn.XLOOKUP(A:A,Sheet1!A:A,Sheet1!M:M) -> 40 | J35: =_xlfn.XLOOKUP(A:A,Sheet1!A:A,Sheet1!O:O) -> 2.4 | K35: =_xlfn.XLOOKUP(A:A,Sheet1!A:A,Sheet1!P:P) -> Yes | L35: =_xlfn.XLOOKUP(A:A,Sheet1!A:A,Sheet1!S:S) -> 0.82
A36: FL250035 | B36: =_xlfn.XLOOKUP(A36,Sheet1!A:A,Sheet1!B:B) -> Jessica Snyder | C36: =_xlfn.XLOOKUP(A:A,Sheet1!A:A,Sheet1!D:D) -> Female | D36: =_xlfn.XLOOKUP(A:A,Sheet1!A:A,Sheet1!F:F) -> 54 | E36: =_xlfn.XLOOKUP(A:A,Sheet1!A:A,Sheet1!G:G) -> United States | F36: =_xlfn.XLOOKUP(A:A,Sheet1!A:A,Sheet1!H:H) -> English | G36: =_xlfn.XLOOKUP(A:A,Sheet1!A:A,Sheet1!I:I) -> Web Development | H36: =_xlfn.XLOOKUP(A:A,Sheet1!A:A,Sheet1!K:K) -> 32 | I36: =_xlfn.XLOOKUP(A:A,Sheet1!A:A,Sheet1!M:M) -> 75 | J36: =_xlfn.XLOOKUP(A:A,Sheet1!A:A,Sheet1!O:O) -> 1 | K36: =_xlfn.XLOOKUP(A:A,Sheet1!A:A,Sheet1!P:P) -> Yes | L36: =_xlfn.XLOOKUP(A:A,Sheet1!A:A,Sheet1!S:S) -> 0.81
A37: FL250036 | B37: =_xlfn.XLOOKUP(A37,Sheet1!A:A,Sheet1!B:B) -> Emily Daniels | C37: =_xlfn.XLOOKUP(A:A,Sheet1!A:A,Sheet1!D:D) -> Female | D37: =_xlfn.XLOOKUP(A:A,Sheet1!A:A,Sheet1!F:F) -> 52 | E37: =_xlfn.XLOOKUP(A:A,Sheet1!A:A,Sheet1!G:G) -> South Korea | F37: =_xlfn.XLOOKUP(A:A,Sheet1!A:A,Sheet1!H:H) -> Korean | G37: =_xlfn.XLOOKUP(A:A,Sheet1!A:A,Sheet1!I:I) -> Web Development | H37: =_xlfn.XLOOKUP(A:A,Sheet1!A:A,Sheet1!K:K) -> 28 | I37: =_xlfn.XLOOKUP(A:A,Sheet1!A:A,Sheet1!M:M) -> 20 | J37: =_xlfn.XLOOKUP(A:A,Sheet1!A:A,Sheet1!O:O) -> 2.5125695 | K37: =_xlfn.XLOOKUP(A:A,Sheet1!A:A,Sheet1!P:P) -> No | L37: =_xlfn.XLOOKUP(A:A,Sheet1!A:A,Sheet1!S:S) -> 0.79269417
A38: FL250037 | B38: =_xlfn.XLOOKUP(A38,Sheet1!A:A,Sheet1!B:B) -> Jamie Ramirez | C38: =_xlfn.XLOOKUP(A:A,Sheet1!A:A,Sheet1!D:D) -> Female | D38: =_xlfn.XLOOKUP(A:A,Sheet1!A:A,Sheet1!F:F) -> 42 | E38: =_xlfn.XLOOKUP(A:A,Sheet1!A:A,Sheet1!G:G) -> Japan | F38: =_xlfn.XLOOKUP(A:A,Sheet1!A:A,Sheet1!H:H) -> Japanese | G38: =_xlfn.XLOOKUP(A:A,Sheet1!A:A,Sheet1!I:I) -> Mobile Apps | H38: =_xlfn.XLOOKUP(A:A,Sheet1!A:A,Sheet1!K:K) -> 6 | I38: =_xlfn.XLOOKUP(A:A,Sheet1!A:A,Sheet1!M:M) -> 40 | J38: =_xlfn.XLOOKUP(A:A,Sheet1!A:A,Sheet1!O:O) -> 2.5125695 | K38: =_xlfn.XLOOKUP(A:A,Sheet1!A:A,Sheet1!P:P) -> No | L38: =_xlfn.XLOOKUP(A:A,Sheet1!A:A,Sheet1!S:S) -> 0.63
A39: FL250038 | B39: =_xlfn.XLOOKUP(A39,Sheet1!A:A,Sheet1!B:B) -> Amy Harrison | C39: =_xlfn.XLOOKUP(A:A,Sheet1!A:A,Sheet1!D:D) -> Female | D39: =_xlfn.XLOOKUP(A:A,Sheet1!A:A,Sheet1!F:F) -> 29 | E39: =_xlfn.XLOOKUP(A:A,Sheet1!A:A,Sheet1!G:G) -> Netherlands | F39: =_xlfn.XLOOKUP(A:A,Sheet1!A:A,Sheet1!H:H) -> Dutch | G39: =_xlfn.XLOOKUP(A:A,Sheet1!A:A,Sheet1!I:I) -> Graphic Design | H39: =_xlfn.XLOOKUP(A:A,Sheet1!A:A,Sheet1!K:K) -> 10 | I39: =_xlfn.XLOOKUP(A:A,Sheet1!A:A,Sheet1!M:M) -> 40 | J39: =_xlfn.XLOOKUP(A:A,Sheet1!A:A,Sheet1!O:O) -> 2.2 | K39: =_xlfn.XLOOKUP(A:A,Sheet1!A:A,Sheet1!P:P) -> No | L39: =_xlfn.XLOOKUP(A:A,Sheet1!A:A,Sheet1!S:S) -> 0.67
A40: FL250039 | B40: =_xlfn.XLOOKUP(A40,Sheet1!A:A,Sheet1!B:B) -> Melinda White | C40: =_xlfn.XLOOKUP(A:A,Sheet1!A:A,Sheet1!D:D) -> Female | D40: =_xlfn.XLOOKUP(A:A,Sheet1!A:A,Sheet1!F:F) -> 42 | E40: =_xlfn.XLOOKUP(A:A,Sheet1!A:A,Sheet1!G:G) -> South Africa | F40: =_xlfn.XLOOKUP(A:A,Sheet1!A:A,Sheet1!H:H) -> Afrikaans | G40: =_xlfn.XLOOKUP(A:A,Sheet1!A:A,Sheet1!I:I) -> Mobile Apps | H40: =_xlfn.XLOOKUP(A:A,Sheet1!A:A,Sheet1!K:K) -> 23 | I40: =_xlfn.XLOOKUP(A:A,Sheet1!A:A,Sheet1!M:M) -> 50 | J40: =_xlfn.XLOOKUP(A:A,Sheet1!A:A,Sheet1!O:O) -> 3.2 | K40: =_xlfn.XLOOKUP(A:A,Sheet1!A:A,Sheet1!P:P) -> Yes | L40: =_xlfn.XLOOKUP(A:A,Sheet1!A:A,Sheet1!S:S) -> 0.79269417
A41: FL250040 | B41: =_xlfn.XLOOKUP(A41,Sheet1!A:A,Sheet1!B:B) -> James Hernandez | C41: =_xlfn.XLOOKUP(A:A,Sheet1!A:A,Sheet1!D:D) -> Male | D41: =_xlfn.XLOOKUP(A:A,Sheet1!A:A,Sheet1!F:F) -> 60 | E41: =_xlfn.XLOOKUP(A:A,Sheet1!A:A,Sheet1!G:G) -> Japan | F41: =_xlfn.XLOOKUP(A:A,Sheet1!A:A,Sheet1!H:H) -> Japanese | G41: =_xlfn.XLOOKUP(A:A,Sheet1!A:A,Sheet1!I:I) -> Web Development | H41: =_xlfn.XLOOKUP(A:A,Sheet1!A:A,Sheet1!K:K) -> 13 | I41: =_xlfn.XLOOKUP(A:A,Sheet1!A:A,Sheet1!M:M) -> 20 | J41: =_xlfn.XLOOKUP(A:A,Sheet1!A:A,Sheet1!O:O) -> 3.6 | K41: =_xlfn.XLOOKUP(A:A,Sheet1!A:A,Sheet1!P:P) -> No | L41: =_xlfn.XLOOKUP(A:A,Sheet1!A:A,Sheet1!S:S) -> 0.8
A42: FL250041 | B42: =_xlfn.XLOOKUP(A42,Sheet1!A:A,Sheet1!B:B) -> Angelica Rogers | C42: =_xlfn.XLOOKUP(A:A,Sheet1!A:A,Sheet1!D:D) -> Female | D42: =_xlfn.XLOOKUP(A:A,Sheet1!A:A,Sheet1!F:F) -> 59 | E42: =_xlfn.XLOOKUP(A:A,Sheet1!A:A,Sheet1!G:G) -> United Kingdom | F42: =_xlfn.XLOOKUP(A:A,Sheet1!A:A,Sheet1!H:H) -> English | G42: =_xlfn.XLOOKUP(A:A,Sheet1!A:A,Sheet1!I:I) -> AI | H42: =_xlfn.XLOOKUP(A:A,Sheet1!A:A,Sheet1!K:K) -> 3 | I42: =_xlfn.XLOOKUP(A:A,Sheet1!A:A,Sheet1!M:M) -> 50 | J42: 0 | K42: =_xlfn.XLOOKUP(A:A,Sheet1!A:A,Sheet1!P:P) -> No | L42: =_xlfn.XLOOKUP(A:A,Sheet1!A:A,Sheet1!S:S) -> 0.79269417
A43: FL250042 | B43: =_xlfn.XLOOKUP(A43,Sheet1!A:A,Sheet1!B:B) -> Savannah Williams | C43: =_xlfn.XLOOKUP(A:A,Sheet1!A:A,Sheet1!D:D) -> Female | D43: =_xlfn.XLOOKUP(A:A,Sheet1!A:A,Sheet1!F:F) -> 21 | E43: =_xlfn.XLOOKUP(A:A,Sheet1!A:A,Sheet1!G:G) -> Canada | F43: =_xlfn.XLOOKUP(A:A,Sheet1!A:A,Sheet1!H:H) -> English | G43: =_xlfn.XLOOKUP(A:A,Sheet1!A:A,Sheet1!I:I) -> Web Development | H43: =_xlfn.XLOOKUP(A:A,Sheet1!A:A,Sheet1!K:K) -> 0 | I43: =_xlfn.XLOOKUP(A:A,Sheet1!A:A,Sheet1!M:M) -> 30 | J43: =_xlfn.XLOOKUP(A:A,Sheet1!A:A,Sheet1!O:O) -> 2.7 | K43: =_xlfn.XLOOKUP(A:A,Sheet1!A:A,Sheet1!P:P) -> Yes | L43: =_xlfn.XLOOKUP(A:A,Sheet1!A:A,Sheet1!S:S) -> 0.84
A44: FL250043 | B44: =_xlfn.XLOOKUP(A44,Sheet1!A:A,Sheet1!B:B) -> Kaitlyn Schmidt | C44: =_xlfn.XLOOKUP(A:A,Sheet1!A:A,Sheet1!D:D) -> Female | D44: =_xlfn.XLOOKUP(A:A,Sheet1!A:A,Sheet1!F:F) -> 35 | E44: =_xlfn.XLOOKUP(A:A,Sheet1!A:A,Sheet1!G:G) -> Germany | F44: =_xlfn.XLOOKUP(A:A,Sheet1!A:A,Sheet1!H:H) -> German | G44: =_xlfn.XLOOKUP(A:A,Sheet1!A:A,Sheet1!I:I) -> DevOps | H44: =_xlfn.XLOOKUP(A:A,Sheet1!A:A,Sheet1!K:K) -> 10 | I44: =_xlfn.XLOOKUP(A:A,Sheet1!A:A,Sheet1!M:M) -> 50 | J44: 0 | K44: =_xlfn.XLOOKUP(A:A,Sheet1!A:A,Sheet1!P:P) -> No | L44: =_xlfn.XLOOKUP(A:A,Sheet1!A:A,Sheet1!S:S) -> 0.79269417
A45: FL250044 | B45: =_xlfn.XLOOKUP(A45,Sheet1!A:A,Sheet1!B:B) -> Jason Singh | C45: =_xlfn.XLOOKUP(A:A,Sheet1!A:A,Sheet1!D:D) -> Male | D45: =_xlfn.XLOOKUP(A:A,Sheet1!A:A,Sheet1!F:F) -> 41 | E45: =_xlfn.XLOOKUP(A:A,Sheet1!A:A,Sheet1!G:G) -> United Kingdom | F45: =_xlfn.XLOOKUP(A:A,Sheet1!A:A,Sheet1!H:H) -> English | G45: =_xlfn.XLOOKUP(A:A,Sheet1!A:A,Sheet1!I:I) -> Data Analysis | H45: =_xlfn.XLOOKUP(A:A,Sheet1!A:A,Sheet1!K:K) -> 9 | I45: =_xlfn.XLOOKUP(A:A,Sheet1!A:A,Sheet1!M:M) -> 20 | J45: =_xlfn.XLOOKUP(A:A,Sheet1!A:A,Sheet1!O:O) -> 2.8 | K45: =_xlfn.XLOOKUP(A:A,Sheet1!A:A,Sheet1!P:P) -> Yes | L45: =_xlfn.XLOOKUP(A:A,Sheet1!A:A,Sheet1!S:S) -> 0.63
A46: FL250045 | B46: =_xlfn.XLOOKUP(A46,Sheet1!A:A,Sheet1!B:B) -> Michelle Ramirez | C46: =_xlfn.XLOOKUP(A:A,Sheet1!A:A,Sheet1!D:D) -> Female | D46: =_xlfn.XLOOKUP(A:A,Sheet1!A:A,Sheet1!F:F) -> 51 | E46: =_xlfn.XLOOKUP(A:A,Sheet1!A:A,Sheet1!G:G) -> Netherlands | F46: =_xlfn.XLOOKUP(A:A,Sheet1!A:A,Sheet1!H:H) -> Dutch | G46: =_xlfn.XLOOKUP(A:A,Sheet1!A:A,Sheet1!I:I) -> Machine Learning | H46: =_xlfn.XLOOKUP(A:A,Sheet1!A:A,Sheet1!K:K) -> 23 | I46: =_xlfn.XLOOKUP(A:A,Sheet1!A:A,Sheet1!M:M) -> 20 | J46: =_xlfn.XLOOKUP(A:A,Sheet1!A:A,Sheet1!O:O) -> 2.5 | K46: =_xlfn.XLOOKUP(A:A,Sheet1!A:A,Sheet1!P:P) -> No | L46: =_xlfn.XLOOKUP(A:A,Sheet1!A:A,Sheet1!S:S) -> 0.8
A47: FL250046 | B47: =_xlfn.XLOOKUP(A47,Sheet1!A:A,Sheet1!B:B) -> James Brown | C47: =_xlfn.XLOOKUP(A:A,Sheet1!A:A,Sheet1!D:D) -> Male | D47: =_xlfn.XLOOKUP(A:A,Sheet1!A:A,Sheet1!F:F) -> 41 | E47: =_xlfn.XLOOKUP(A:A,Sheet1!A:A,Sheet1!G:G) -> South Africa | F47: =_xlfn.XLOOKUP(A:A,Sheet1!A:A,Sheet1!H:H) -> Afrikaans | G47: =_xlfn.XLOOKUP(A:A,Sheet1!A:A,Sheet1!I:I) -> Web Development | H47: =_xlfn.XLOOKUP(A:A,Sheet1!A:A,Sheet1!K:K) -> 9 | I47: =_xlfn.XLOOKUP(A:A,Sheet1!A:A,Sheet1!M:M) -> 75 | J47: =_xlfn.XLOOKUP(A:A,Sheet1!A:A,Sheet1!O:O) -> 4.9 | K47: =_xlfn.XLOOKUP(A:A,Sheet1!A:A,Sheet1!P:P) -> Yes | L47: =_xlfn.XLOOKUP(A:A,Sheet1!A:A,Sheet1!S:S) -> 0.74
A48: FL250047 | B48: =_xlfn.XLOOKUP(A48,Sheet1!A:A,Sheet1!B:B) -> Samantha Simmons | C48: =_xlfn.XLOOKUP(A:A,Sheet1!A:A,Sheet1!D:D) -> Female | D48: =_xlfn.XLOOKUP(A:A,Sheet1!A:A,Sheet1!F:F) -> 47 | E48: =_xlfn.XLOOKUP(A:A,Sheet1!A:A,Sheet1!G:G) -> Egypt | F48: =_xlfn.XLOOKUP(A:A,Sheet1!A:A,Sheet1!H:H) -> Arabic | G48: =_xlfn.XLOOKUP(A:A,Sheet1!A:A,Sheet1!I:I) -> DevOps | H48: =_xlfn.XLOOKUP(A:A,Sheet1!A:A,Sheet1!K:K) -> 15 | I48: =_xlfn.XLOOKUP(A:A,Sheet1!A:A,Sheet1!M:M) -> 30 | J48: =_xlfn.XLOOKUP(A:A,Sheet1!A:A,Sheet1!O:O) -> 4.5 | K48: =_xlfn.XLOOKUP(A:A,Sheet1!A:A,Sheet1!P:P) -> Yes | L48: =_xlfn.XLOOKUP(A:A,Sheet1!A:A,Sheet1!S:S) -> 0.85
A49: FL250048 | B49: =_xlfn.XLOOKUP(A49,Sheet1!A:A,Sheet1!B:B) -> Chase Mason | C49: =_xlfn.XLOOKUP(A:A,Sheet1!A:A,Sheet1!D:D) -> Male | D49: =_xlfn.XLOOKUP(A:A,Sheet1!A:A,Sheet1!F:F) -> 25 | E49: =_xlfn.XLOOKUP(A:A,Sheet1!A:A,Sheet1!G:G) -> China | F49: =_xlfn.XLOOKUP(A:A,Sheet1!A:A,Sheet1!H:H) -> Mandarin | G49: =_xlfn.XLOOKUP(A:A,Sheet1!A:A,Sheet1!I:I) -> Graphic Design | H49: =_xlfn.XLOOKUP(A:A,Sheet1!A:A,Sheet1!K:K) -> 4 | I49: =_xlfn.XLOOKUP(A:A,Sheet1!A:A,Sheet1!M:M) -> 50 | J49: =_xlfn.XLOOKUP(A:A,Sheet1!A:A,Sheet1!O:O) -> 2.7 | K49: =_xlfn.XLOOKUP(A:A,Sheet1!A:A,Sheet1!P:P) -> No | L49: =_xlfn.XLOOKUP(A:A,Sheet1!A:A,Sheet1!S:S) -> 0.77
A50: FL250049 | B50: =_xlfn.XLOOKUP(A50,Sheet1!A:A,Sheet1!B:B) -> Dominique Ward | C50: =_xlfn.XLOOKUP(A:A,Sheet1!A:A,Sheet1!D:D) -> Female | D50: =_xlfn.XLOOKUP(A:A,Sheet1!A:A,Sheet1!F:F) -> 25 | E50: =_xlfn.XLOOKUP(A:A,Sheet1!A:A,Sheet1!G:G) -> Mexico | F50: =_xlfn.XLOOKUP(A:A,Sheet1!A:A,Sheet1!H:H) -> Spanish | G50: =_xlfn.XLOOKUP(A:A,Sheet1!A:A,Sheet1!I:I) -> Mobile Apps | H50: =_xlfn.XLOOKUP(A:A,Sheet1!A:A,Sheet1!K:K) -> 7 | I50: =_xlfn.XLOOKUP(A:A,Sheet1!A:A,Sheet1!M:M) -> 20 | J50: =_xlfn.XLOOKUP(A:A,Sheet1!A:A,Sheet1!O:O) -> 1.9 | K50: =_xlfn.XLOOKUP(A:A,Sheet1!A:A,Sheet1!P:P) -> No | L50: =_xlfn.XLOOKUP(A:A,Sheet1!A:A,Sheet1!S:S) -> 0.79269417
...

Sheet Pivot Table
A1: Row Labels | B1: Average of Rating | D1: Row Labels | E1: Count of Freelancer_ID | G1: Row Labels | H1: Count of Freelancer_ID
A2: AI | B2: 2.4273826 | D2: 0 | E2: 72 | G2: 20 | H2: 142
A3: Blockchain Development | B3: 2.3823889 | D3: 1 | E3: 64 | G3: 30 | H3: 150
A4: Cybersecurity | B4: 2.475734 | D4: 2 | E4: 67 | G4: 40 | H4: 265
A5: Data Analysis | B5: 2.4356843 | D5: 3 | E5: 51 | G5: 50 | H5: 152
A6: DevOps | B6: 2.7867243 | D6: 4 | E6: 49 | G6: 75 | H6: 134
A7: Graphic Design | B7: 2.5107587 | D7: 5 | E7: 37 | G7: 100 | H7: 157
A8: Machine Learning | B8: 2.5688232 | D8: 6 | E8: 40 | G8: Grand Total | H8: 1000
A9: Mobile Apps | B9: 2.5421678 | D9: 7 | E9: 30
A10: UI/UX Design | B10: 2.5229409 | D10: 8 | E10: 37
A11: Web Development | B11: 2.4435163 | D11: 9 | E11: 88 | G11: Row Labels | H11: Average of Hourly Rate (USD)
A12: Grand Total | B12: 2.5125695 | D12: 10 | E12: 36 | G12: AI | H12: 51.35
D13: 11 | E13: 43 | G13: Blockchain Development | H13: 49.047619
D14: 12 | E14: 26 | G14: Cybersecurity | H14: 53.197674
A15: Row Labels | B15: Count of Freelancer_ID | D15: 13 | E15: 36 | G15: Data Analysis | H15: 51.25
A16: Afrikaans | B16: 44 | D16: 14 | E16: 25 | G16: DevOps | H16: 52.723214
A17: Arabic | B17: 42 | D17: 15 | E17: 28 | G17: Graphic Design | H17: 48.548387
A18: Dutch | B18: 51 | D18: 16 | E18: 15 | G18: Machine Learning | H18: 51.55914
A19: English | B19: 215 | D19: 17 | E19: 21 | G19: Mobile Apps | H19: 50.490196
A20: French | B20: 44 | D20: 18 | E20: 19 | G20: UI/UX Design | H20: 51.788991
A21: German | B21: 52 | D21: 19 | E21: 18 | G21: Web Development | H21: 52.884615
A22: Hindi | B22: 45 | D22: 20 | E22: 21 | G22: Grand Total | H22: 51.29
A23: Indonesian | B23: 46 | D23: 21 | E23: 29
A24: Italian | B24: 42 | D24: 22 | E24: 22 | G24: Row Labels | H24: Count of Freelancer_ID
A25: Japanese | B25: 37 | D25: 23 | E25: 10 | G25: Argentina | H25: 47
A26: Korean | B26: 68 | D26: 24 | E26: 11 | G26: Australia | H26: 51
A27: Mandarin | B27: 49 | D27: 25 | E27: 9 | G27: Brazil | H27: 31
A28: Portuguese | B28: 31 | D28: 26 | E28: 5 | G28: Canada | H28: 65
A29: Russian | B29: 47 | D29: 27 | E29: 7 | G29: China | H29: 49
A30: Spanish | B30: 142 | D30: 28 | E30: 10 | G30: Egypt | H30: 42
A31: Turkish | B31: 45 | D31: 29 | E31: 8 | G31: France | H31: 44
A32: Grand Total | B32: 1000 | D32: 30 | E32: 11 | G32: Germany | H32: 52
D33: 31 | E33: 6 | G33: India | H33: 45
D34: 32 | E34: 10 | G34: Indonesia | H34: 46
D35: 33 | E35: 13 | G35: Italy | H35: 42
D36: 34 | E36: 6 | G36: Japan | H36: 37
D37: 35 | E37: 5 | G37: Mexico | H37: 50
D38: 37 | E38: 5 | G38: Netherlands | H38: 51
D39: 38 | E39: 1 | G39: Russia | H39: 47
D40: 39 | E40: 4 | G40: South Africa | H40: 44
...
